<?xml version="1.0" encoding="UTF-8"?>
<testng-results ignored="0" total="2" passed="1" failed="1" skipped="0">
  <reporter-output>
  </reporter-output>
  <suite started-at="2023-09-12T18:26:59Z" name="Default suite" finished-at="2023-09-12T18:27:01Z" duration-ms="1268">
    <groups>
    </groups>
    <test started-at="2023-09-12T18:26:59Z" name="Default test" finished-at="2023-09-12T18:27:01Z" duration-ms="1268">
      <class name="Test.Net.NewTest1">
        <test-method is-config="true" signature="config()[pri:0, instance:Test.Net.NewTest1@3adcc812]" started-at="2023-09-12T18:26:59Z" name="config" finished-at="2023-09-12T18:27:00Z" duration-ms="504" status="PASS">
          <reporter-output>
          </reporter-output>
        </test-method> <!-- config -->
        <test-method signature="test1()[pri:0, instance:Test.Net.NewTest1@3adcc812]" started-at="2023-09-12T18:27:00Z" name="test1" finished-at="2023-09-12T18:27:00Z" duration-ms="57" status="PASS">
          <reporter-output>
          </reporter-output>
        </test-method> <!-- test1 -->
        <test-method is-config="true" signature="getData(org.testng.ITestResult)[pri:0, instance:Test.Net.NewTest1@3adcc812]" started-at="2023-09-12T18:27:00Z" name="getData" finished-at="2023-09-12T18:27:00Z" duration-ms="3" status="PASS">
          <params>
            <param index="0">
              <value>
                <![CDATA[[TestResult name=test1 status=SUCCESS method=NewTest1.test1()[pri:0, instance:Test.Net.NewTest1@3adcc812] output={null}]]]>
              </value>
            </param>
          </params>
          <reporter-output>
          </reporter-output>
        </test-method> <!-- getData -->
        <test-method signature="test2()[pri:0, instance:Test.Net.NewTest1@3adcc812]" started-at="2023-09-12T18:27:00Z" name="test2" finished-at="2023-09-12T18:27:00Z" duration-ms="6" status="FAIL">
          <exception class="java.lang.AssertionError">
            <message>
              <![CDATA[expected [true] but found [false]]]>
            </message>
            <full-stacktrace>
              <![CDATA[java.lang.AssertionError: expected [true] but found [false]
at org.testng.Assert.fail(Assert.java:96)
at org.testng.Assert.failNotEquals(Assert.java:776)
at org.testng.Assert.assertTrue(Assert.java:44)
at org.testng.Assert.assertTrue(Assert.java:54)
at Test.Net.NewTest1.test2(NewTest1.java:42)
at java.base/jdk.internal.reflect.NativeMethodAccessorImpl.invoke0(Native Method)
at java.base/jdk.internal.reflect.NativeMethodAccessorImpl.invoke(NativeMethodAccessorImpl.java:77)
at java.base/jdk.internal.reflect.DelegatingMethodAccessorImpl.invoke(DelegatingMethodAccessorImpl.java:43)
at java.base/java.lang.reflect.Method.invoke(Method.java:568)
at org.testng.internal.MethodInvocationHelper.invokeMethod(MethodInvocationHelper.java:124)
at org.testng.internal.Invoker.invokeMethod(Invoker.java:580)
at org.testng.internal.Invoker.invokeTestMethod(Invoker.java:716)
at org.testng.internal.Invoker.invokeTestMethods(Invoker.java:988)
at org.testng.internal.TestMethodWorker.invokeTestMethods(TestMethodWorker.java:125)
at org.testng.internal.TestMethodWorker.run(TestMethodWorker.java:109)
at org.testng.TestRunner.privateRun(TestRunner.java:648)
at org.testng.TestRunner.run(TestRunner.java:505)
at org.testng.SuiteRunner.runTest(SuiteRunner.java:455)
at org.testng.SuiteRunner.runSequentially(SuiteRunner.java:450)
at org.testng.SuiteRunner.privateRun(SuiteRunner.java:415)
at org.testng.SuiteRunner.run(SuiteRunner.java:364)
at org.testng.SuiteRunnerWorker.runSuite(SuiteRunnerWorker.java:52)
at org.testng.SuiteRunnerWorker.run(SuiteRunnerWorker.java:84)
at org.testng.TestNG.runSuitesSequentially(TestNG.java:1208)
at org.testng.TestNG.runSuitesLocally(TestNG.java:1137)
at org.testng.TestNG.runSuites(TestNG.java:1049)
at org.testng.TestNG.run(TestNG.java:1017)
at org.testng.remote.AbstractRemoteTestNG.run(AbstractRemoteTestNG.java:115)
at org.testng.remote.RemoteTestNG.initAndRun(RemoteTestNG.java:251)
at org.testng.remote.RemoteTestNG.main(RemoteTestNG.java:77)
]]>
            </full-stacktrace>
          </exception> <!-- java.lang.AssertionError -->
          <reporter-output>
          </reporter-output>
        </test-method> <!-- test2 -->
        <test-method is-config="true" signature="getData(org.testng.ITestResult)[pri:0, instance:Test.Net.NewTest1@3adcc812]" started-at="2023-09-12T18:27:00Z" name="getData" finished-at="2023-09-12T18:27:00Z" duration-ms="31" status="PASS">
          <params>
            <param index="0">
              <value>
                <![CDATA[[TestResult name=test2 status=FAILURE method=NewTest1.test2()[pri:0, instance:Test.Net.NewTest1@3adcc812] output={null}]]]>
              </value>
            </param>
          </params>
          <reporter-output>
          </reporter-output>
        </test-method> <!-- getData -->
        <test-method is-config="true" signature="flush1()[pri:0, instance:Test.Net.NewTest1@3adcc812]" started-at="2023-09-12T18:27:00Z" name="flush1" finished-at="2023-09-12T18:27:01Z" duration-ms="607" status="PASS">
          <reporter-output>
          </reporter-output>
        </test-method> <!-- flush1 -->
      </class> <!-- Test.Net.NewTest1 -->
    </test> <!-- Default test -->
  </suite> <!-- Default suite -->
</testng-results>
